Workbook

Sheet Закупка
B1: комментарий логиста? как в накладной? | C1: Codigo | D1: цена закупки за пачку | E1: сколько пачек купили | F1: внтури пачки штук? | G1: M | H1: P | I1: A | J1: G | K1: B | L1: брак возврат | M1: ok? | O1: ожидаемое кол-во штук товара | P1: новая цена | Q1: цена в базе | R1: фото | S1: название с поиском | T1: Holded артикул | U1: название с holded | V1: codigo de fabricasion | W1: img | X1: цена закупки из базы | Y1: карточка | Z1: карточка товара | AA1: примечания от саши
B2: 45845 | C2: Логист: Саша | P2: 45754 | R2: Бек Офис: Соня
B3: Фактура 1 | C3: 001797 / 2026 | M3: =IF(E3<>"", E3 - SUM(G3:L3), "") | O3: =IF(AND(F3<>"", E3<>""), F3*E3, "") | Z3: {=IF(R4 = "", "", HYPERLINK("https://app.holded.com/products/" & INDEX(products!A:A, MATCH(TEXT(R4, "0"), TEXT(products!B:B, "0"), 0)), "Открыть карточку товара"))} -> #N/A
A4: 1.1 | B4: RANUNCULUS CLOONEY TUAREQ | D4: 1.11 | E4: 3 | F4: 10 | J4: 3 | M4: =IF(E4<>"", E4 - SUM(G4:L4), "") -> 0 | O4: =IF(AND(F4<>"", E4<>""), F4*E4, "") -> 30 | P4: 3 | Q4: 2.999997 | R4: =IMAGE(W4) | S4: 8400518 - RANUNCULUS - Butterfly - flor ( RANUBUBL, RANUBUSA, 174946, 147132, 126830) | T4: 8400518 | U4: RANUNCULUS - Butterfly - flor | V4: RANUBUBL, RANUBUSA, 174946, 147132, 126830 | W4: https://drive.google.com/uc?export=view&id=1mbmVjM82bGnM8nxdZnDYmJjSQLnHiol0
A5: 1.2 | B5: RANUNCULUS CLOONEY GRAND PASTEL | D5: 1.11 | E5: 6 | F5: 10 | K5: 6 | M5: =IF(E5<>"", E5 - SUM(G5:L5), "") -> 0 | O5: =IF(AND(F5<>"", E5<>""), F5*E5, "") -> 60 | P5: 3 | Q5: 2.999997 | R5: =IMAGE(W5) | S5: 8400518 - RANUNCULUS - Butterfly - flor ( RANUBUBL, RANUBUSA, 174946, 147132, 126830) | T5: 8400518 | U5: RANUNCULUS - Butterfly - flor | V5: RANUBUBL, RANUBUSA, 174946, 147132, 126830 | W5: https://drive.google.com/uc?export=view&id=1mbmVjM82bGnM8nxdZnDYmJjSQLnHiol0
A6: 1.3 | B6: ALSTROEMERIA SI SOFIENA | D6: 0.75 | E6: 6 | F6: 10 | H6: 2 | J6: 2 | K6: 2 | M6: =IF(E6<>"", E6 - SUM(G6:L6), "") -> 0 | O6: =IF(AND(F6<>"", E6<>""), F6*E6, "") -> 60 | Q6: 2.999997 | R6: =IMAGE(W6) | S6: 8400154 - ALSTROEMERIA - flor (00027, 11920, 146548, 148465, ALS VA, 148462, 148466, 11920, ALS-P, 137896, 137077, 137894, 148289, 148469, ALSTROEMERIES ALSTROEMERIA, ALSP, 11920) | T6: 8400154 | U6: ALSTROEMERIA - flor | V6: 00027, 11920, 146548, 148465, ALS VA, 148462, 148466, 11920, ALS-P, 137896, 137077, 137894, 148289, 148469, ALSTROEMERIES ALSTROEMERIA, ALSP, 11920 | W6: https://drive.google.com/uc?export=view&id=1hD_EIkM8w5p_WtnrcMdhYX6szEYoVelf | X6: 0.15
A7: 1.4 | B7: ROSA LARGE BELLE ROSE | D7: 0.58 | E7: 6 | F7: 10 | K7: 6 | M7: =IF(E7<>"", E7 - SUM(G7:L7), "") -> 0 | O7: =IF(AND(F7<>"", E7<>""), F7*E7, "") -> 60 | P7: 2 | Q7: 1.999998 | R7: =IMAGE(W7) | S7: 8400731 - RS ROSA LA BELLE LOLOMARIK - flor (181496) | T7: 8400731 | U7: RS ROSA LA BELLE LOLOMARIK - flor | V7: 181496 | W7: https://drive.google.com/uc?export=view&id=1fUhUDsiSHWrleyP7h5w_2pEpagbWza0G
A8: 1.5 | B8: ROSA GARDEN PRISCILLA! | D8: 0.71 | E8: 6 | F8: 5 | J8: 2 | K8: 4 | M8: =IF(E8<>"", E8 - SUM(G8:L8), "") -> 0 | O8: =IF(AND(F8<>"", E8<>""), F8*E8, "") -> 30 | Q8: 2.999997 | R8: =IMAGE(W8) | S8: 84001081 - ROSA PRISCILLA - flor () | T8: 84001081 | U8: ROSA PRISCILLA - flor | W8: https://drive.google.com/uc?export=view&id=1dI4YSHY8sPn-AzvYOdjKrrjGMV26hEE0
A9: 1.6 | B9: ROSA GARDEN MIX UHURU | D9: 1.19 | E9: 8 | F9: 6 | K9: 8 | M9: =IF(E9<>"", E9 - SUM(G9:L9), "") -> 0 | O9: =IF(AND(F9<>"", E9<>""), F9*E9, "") -> 48 | P9: 3 | S9: 84001157 - RISA GARDAN MIX - flor/3 () | T9: 84001157 | U9: RISA GARDAN MIX - flor/3 | W9: ❗Ошибка: application/json
A10: 1.7 | B10: ROSA SPRAY CHIMO | D10: 0.77 | E10: 8 | F10: 10 | H10: 2 | J10: 3 | K10: 3 | M10: =IF(E10<>"", E10 - SUM(G10:L10), "") -> 0 | O10: =IF(AND(F10<>"", E10<>""), F10*E10, "") -> 80 | Q10: 2.999997 | R10: =IMAGE(W10) | S10: 8400828 - ROSA CHIMO - flor (135409) | T10: 8400828 | U10: ROSA CHIMO - flor | V10: 135409 | W10: https://drive.google.com/uc?export=view&id=14lKbr1IZa_y54C-n_irMTGAXEPdZJoIn
A11: 1.8 | B11: ROSA SPRAY BIRDS NEST+ | D11: 1.52 | E11: 4 | F11: 10 | J11: 1 | K11: 3 | M11: =IF(E11<>"", E11 - SUM(G11:L11), "") -> 0 | O11: =IF(AND(F11<>"", E11<>""), F11*E11, "") -> 40 | P11: 4 | Q11: 3.999996 | R11: =IMAGE(W11) | S11: 84001078 - ROSA BIRDS NEST - flor () | T11: 84001078 | U11: ROSA BIRDS NEST - flor | W11: https://drive.google.com/uc?export=view&id=1cMWmYq9Ijr9CTBLT1xhfRb5ZQ_GrN7hE
A12: 1.9 | B12: ROSA LARGE CELEB | D12: 0.47 | E12: 6 | F12: 10 | H12: 3 | J12: 3 | M12: =IF(E12<>"", E12 - SUM(G12:L12), "") -> 0 | O12: =IF(AND(F12<>"", E12<>""), F12*E12, "") -> 60 | P12: 3 | Q12: 2.999997 | R12: =IMAGE(W12) | S12: 84001044 - ROSA CELEBRATING HEATHER - flor () | T12: 84001044 | U12: ROSA CELEBRATING HEATHER - flor | W12: https://drive.google.com/uc?export=view&id=14z6focMNsmhbYM377L2M-B88nBfvXnJJ
A13: 1.10 | B13: ARR CACTUS | D13: 10.86 | E13: 18 | F13: 1 | J13: 9 | K13: 9 | M13: =IF(E13<>"", E13 - SUM(G13:L13), "") -> 0 | O13: =IF(AND(F13<>"", E13<>""), F13*E13, "") -> 18 | P13: 22 | Q13: 22 | R13: =IMAGE(W13) | S13: 8400594 - CACTUS - planta/22 (TEST 13 cactus) | T13: 8400594 | U13: CACTUS - planta/22 | V13: TEST 13 cactus | W13: https://drive.google.com/uc?export=view&id=1Q-AyZHgyh6uUyL-RDutGOkXSIkuILjHz
A14: 1.11 | B14: ALOE ARBO | D14: 19.07 | E14: 1 | F14: 1 | J14: 1 | M14: =IF(E14<>"", E14 - SUM(G14:L14), "") -> 0 | O14: =IF(AND(F14<>"", E14<>""), F14*E14, "") -> 1 | P14: 67 | Q14: 66.999999 | R14: =IMAGE(W14) | S14: 84001156 - ALOE ARBO - planta/67 () | T14: 84001156 | U14: ALOE ARBO - planta/67 | W14: https://drive.google.com/uc?export=view&id=1nhRiZiSymvZqgrwdzMgNfzK5d8VGqcGQ
A15: 1.12 | B15: ALOE ARBO | D15: 14.53 | E15: 8 | F15: 1 | J15: 4 | K15: 4 | M15: =IF(E15<>"", E15 - SUM(G15:L15), "") -> 0 | O15: =IF(AND(F15<>"", E15<>""), F15*E15, "") -> 8 | P15: 47 | Q15: 46.999997 | R15: =IMAGE(W15) | S15: 84001155 - ALOE ARBO - planta/47 () | T15: 84001155 | U15: ALOE ARBO - planta/47 | W15: https://drive.google.com/uc?export=view&id=1jKGrPrhB6pvkBpjJKJWeb0LNLwFLMWiM
A16: 1.13 | B16: ARR2 MB GROEN IJZER REK 1 BOL | D16: 9.54 | E16: 8 | F16: 1 | J16: 4 | K16: 4 | M16: =IF(E16<>"", E16 - SUM(G16:L16), "") -> 0 | O16: =IF(AND(F16<>"", E16<>""), F16*E16, "") -> 8 | P16: 22 | Q16: 22 | R16: =IMAGE(W16) | S16: 8400410 - SUCCULENTUS T16, T22 - MIX - planta/22 (6CRASA22, 54, CRASS16 ) | T16: 8400410 | U16: SUCCULENTUS T16, T22 - MIX - planta/22 | V16: 6CRASA22, 54, CRASS16 | W16: https://drive.google.com/uc?export=view&id=1NfWhvI4iOJyVFjUEUpFej-EfjH2FiZmQ
A17: 1.14 | B17: ARR NARCISSUS TETE-A-TETE | D17: 5.69 | E17: 12 | F17: 1 | J17: 6 | K17: 6 | M17: =IF(E17<>"", E17 - SUM(G17:L17), "") -> 0 | O17: =IF(AND(F17<>"", E17<>""), F17*E17, "") -> 12 | P17: 14 | Q17: 13.999997 | R17: =IMAGE(W17) | S17: 84001152 - NARCISO TETE-A-TETE - composición/14 () | T17: 84001152 | U17: NARCISO TETE-A-TETE - composición/14 | W17: https://drive.google.com/uc?export=view&id=1jCZc_-4baAz784L3_VmKEcFHD_O4bGxB
A18: 1.15 | B18: ARR NARCISSUS | D18: 6.53 | E18: 8 | F18: 1 | J18: 4 | K18: 4 | M18: =IF(E18<>"", E18 - SUM(G18:L18), "") -> 0 | O18: =IF(AND(F18<>"", E18<>""), F18*E18, "") -> 8 | Q18: 17.000005 | R18: =IMAGE(W18) | S18: 84001038 - NARCIS MASCOTA - planta /17 () | T18: 84001038 | U18: NARCIS MASCOTA - planta /17 | W18: https://drive.google.com/uc?export=view&id=1ANQILzJ7Mt0PRTsFNY6NHq3nJ6aUQJyJ
A19: 1.16 | B19: ARR2 PL KER BAROK DRACENA | D19: 14.37 | E19: 4 | F19: 1 | J19: 4 | M19: =IF(E19<>"", E19 - SUM(G19:L19), "") -> 0 | O19: =IF(AND(F19<>"", E19<>""), F19*E19, "") -> 4 | P19: 38 | Q19: 37.999995 | R19: =IMAGE(W19) | S19: 84001154 - COMPOSITION DE DRECENA - planta/38 () | T19: 84001154 | U19: COMPOSITION DE DRECENA - planta/38 | W19: https://drive.google.com/uc?export=view&id=1Wq_Uard5MdVY8XSrul4hRMbglxiw4tPZ
A20: 1.17 | B20: ARR2 PL KER BAROK DRACENA | D20: 14.37 | E20: 4 | F20: 1 | K20: 4 | M20: =IF(E20<>"", E20 - SUM(G20:L20), "") -> 0 | O20: =IF(AND(F20<>"", E20<>""), F20*E20, "") -> 4 | P20: 38 | Q20: 37.999995 | R20: =IMAGE(W20) | S20: 84001154 - COMPOSITION DE DRECENA - planta/38 () | T20: 84001154 | U20: COMPOSITION DE DRECENA - planta/38 | W20: https://drive.google.com/uc?export=view&id=1rQlNeojmuigxCKDDyLyE9853PtyPfBIF
A21: 1.18 | B21: ARR2 PL GLAS CILINDER PHAL PAARS | D21: 29.24 | E21: 4 | F21: 1 | J21: 2 | K21: 2 | M21: =IF(E21<>"", E21 - SUM(G21:L21), "") -> 0 | O21: =IF(AND(F21<>"", E21<>""), F21*E21, "") -> 4 | P21: 65 | Q21: 65.000001 | R21: =IMAGE(W21) | S21: 84001153 - ARRANGEMENT DE PHALAENOPSIS - composición/56 () | T21: 84001153 | U21: ARRANGEMENT DE PHALAENOPSIS - composición/56 | W21: https://drive.google.com/uc?export=view&id=1SK1jetqpkHm4wysAal2kTf97P1BEWhpF
A22: 1.19 | B22: CRASSULA OVATA | D22: 100.54 | E22: 1 | F22: 1 | J22: 1 | M22: =IF(E22<>"", E22 - SUM(G22:L22), "") -> 0 | O22: =IF(AND(F22<>"", E22<>""), F22*E22, "") -> 1 | P22: 188 | Q22: 188 | R22: =IMAGE(W22) | S22: 8400365 - ARBOL DE JADE T25 -planta/120 ( ARBOL DE JADE GRANDE (Crassula Ovata) T-25) | T22: 8400365 | U22: ARBOL DE JADE T25 -planta/120 | V22: ARBOL DE JADE GRANDE (Crassula Ovata) T-25 | W22: https://drive.google.com/uc?export=view&id=1lx61k_U5Kp0yFS3ThzMZxvaYOsDd3GCE
A23: 1.20 | B23: CRASSULA OVATA | D23: 94.26 | E23: 1 | F23: 1 | K23: 1 | M23: =IF(E23<>"", E23 - SUM(G23:L23), "") -> 0 | O23: =IF(AND(F23<>"", E23<>""), F23*E23, "") -> 1 | P23: 188 | Q23: 188 | R23: =IMAGE(W23) | S23: 8400365 - ARBOL DE JADE T25 -planta/188 ( ARBOL DE JADE GRANDE (Crassula Ovata) T-25) | T23: 8400365 | U23: ARBOL DE JADE T25 -planta/188 | V23: ARBOL DE JADE GRANDE (Crassula Ovata) T-25 | W23: https://drive.google.com/uc?export=view&id=1lx61k_U5Kp0yFS3ThzMZxvaYOsDd3GCE
A24: 1.21 | B24: CODIAEUM VARI MRS ICETON | D24: 23.43 | E24: 3 | F24: 1 | J24: 3 | M24: =IF(E24<>"", E24 - SUM(G24:L24), "") -> 0 | O24: =IF(AND(F24<>"", E24<>""), F24*E24, "") -> 3 | P24: 36 | Q24: 35.999997 | R24: =IMAGE(W24) | S24: 8400558 - CROTON 50cm - Petra - planta/36 (81945, CROMA20) | T24: 8400558 | U24: CROTON 50cm - Petra - planta/36 | V24: 81945, CROMA20 | W24: https://drive.google.com/uc?export=view&id=1bQ_DhntG2uRO8Okt4v1vWc7zG6mHvaCV
A25: 1.22 | B25: LAVANDULA STOE ANOUK | D25: 6.52 | E25: 6 | F25: 1 | K25: 6 | M25: =IF(E25<>"", E25 - SUM(G25:L25), "") -> 0 | O25: =IF(AND(F25<>"", E25<>""), F25*E25, "") -> 6 | Q25: 14.999996 | R25: =IMAGE(W25) | S25: 8400357 - LAVANDULA T13 - planta (LAV13 LAVANDULA T-13, 42454) | T25: 8400357 | U25: LAVANDULA T13 - planta | V25: LAV13 LAVANDULA T-13, 42454 | W25: https://drive.google.com/uc?export=view&id=1b7R1A9LoTC34-OMZMrvcLKwKIECUi_Os
A26: 1.23 | B26: KALANCHOE LUCKY BELLS | D26: 7.27 | E26: 6 | F26: 1 | J26: 6 | M26: =IF(E26<>"", E26 - SUM(G26:L26), "") -> 0 | O26: =IF(AND(F26<>"", E26<>""), F26*E26, "") -> 6 | P26: 18 | Q26: 18.000004 | R26: =IMAGE(W26) | S26: 8400448 - KALANCHOE T25 - Pumila - planta/18 (KAL-P KALANCHOE PUMILA T-25 planta, KCALT) | T26: 8400448 | U26: KALANCHOE T25 - Pumila - planta/18 | V26: KAL-P KALANCHOE PUMILA T-25 planta, KCALT | W26: https://drive.google.com/uc?export=view&id=1OsLbWUraJBcbC_4ErrdcoBAP-oM2MkBa
A27: 1.24 | B27: EUPHORBIA TRIGONA | D27: 4.09 | E27: 10 | F27: 1 | K27: 10 | M27: =IF(E27<>"", E27 - SUM(G27:L27), "") -> 0 | O27: =IF(AND(F27<>"", E27<>""), F27*E27, "") -> 10 | Q27: 22 | R27: =IMAGE(W27) | S27: 8400556 - EUPHORBIA 30cm -Milii - planta/22 (174581, EUV) | T27: 8400556 | U27: EUPHORBIA 30cm -Milii - planta/22 | V27: 174581, EUV | W27: https://drive.google.com/uc?export=view&id=12K7rSNmKuUyPiVea-hixINhAgk9pFzEX
A28: 1.25 | B28: PTPB6537 ARRANGEMENTEN PASEN | D28: 29.75 | E28: 2 | F28: 1 | J28: 1 | K28: 1 | M28: =IF(E28<>"", E28 - SUM(G28:L28), "") -> 0 | O28: =IF(AND(F28<>"", E28<>""), F28*E28, "") -> 2 | P28: 65 | Q28: 65.000001 | R28: =IMAGE(W28) | S28: 84001153 - ARRANGEMENT DE PHALAENOPSIS - composición/56 () | T28: 84001153 | U28: ARRANGEMENT DE PHALAENOPSIS - composición/56 | W28: https://drive.google.com/uc?export=view&id=1SK1jetqpkHm4wysAal2kTf97P1BEWhpF
A29: 1.26 | B29: PTPB6525 ARRANGEMENTEN PASEN | D29: 29.75 | E29: 2 | F29: 1 | J29: 1 | K29: 1 | M29: =IF(E29<>"", E29 - SUM(G29:L29), "") -> 0 | O29: =IF(AND(F29<>"", E29<>""), F29*E29, "") -> 2 | P29: 65 | Q29: 65.000001 | R29: =IMAGE(W29) | S29: 84001153 - ARRANGEMENT DE PHALAENOPSIS - composición/56 () | T29: 84001153 | U29: ARRANGEMENT DE PHALAENOPSIS - composición/56 | W29: https://drive.google.com/uc?export=view&id=1SK1jetqpkHm4wysAal2kTf97P1BEWhpF
A30: 1.27 | B30: PHALAENOPSIS OTHER YELLOW | D30: 15.78 | E30: 6 | F30: 1 | J30: 6 | M30: =IF(E30<>"", E30 - SUM(G30:L30), "") -> 0 | O30: =IF(AND(F30<>"", E30<>""), F30*E30, "") -> 6 | P30: 28 | Q30: 28.000005 | R30: =IMAGE(W30) | S30: 8400391 - PHALAENOPSIS MIX - planta/28 (161202, 179376, 144102, 179304, 191963, 135419, 182797, 127000, 191284) | T30: 8400391 | U30: PHALAENOPSIS MIX - planta/28 | V30: 161202, 179376, 144102, 179304, 191963, 135419, 182797, 127000, 191284 | W30: https://drive.google.com/uc?export=view&id=1r3AGRebywrGIf9rgKm41rhLoFBf_VJYs
A31: 1.28 | B31: SUCCULENTEN OTHER | D31: 10.25 | E31: 3 | F31: 1 | K31: 3 | M31: =IF(E31<>"", E31 - SUM(G31:L31), "") -> 0 | O31: =IF(AND(F31<>"", E31<>""), F31*E31, "") -> 3 | P31: 28 | Q31: 28.000005 | R31: =IMAGE(W31) | S31: 8400591 - SUCCULENTUS OTHER - planta/28 (CRASSCI-9, AEON.012) | T31: 8400591 | U31: SUCCULENTUS OTHER - planta/28 | V31: CRASSCI-9, AEON.012 | W31: https://drive.google.com/uc?export=view&id=1sZGDN8zhyq19KpYdDu_85JCqZfDsrTCK
A32: 1.29 | B32: RHIPSALIS MIX | D32: 4.33 | E32: 24 | F32: 1 | J32: 12 | K32: 12 | M32: =IF(E32<>"", E32 - SUM(G32:L32), "") -> 0 | O32: =IF(AND(F32<>"", E32<>""), F32*E32, "") -> 24 | P32: 12 | Q32: 11.999999 | R32: =IMAGE(W32) | S32: 8400895 - RHIPSALIS MIX - T17 planta colganta (83612) | T32: 8400895 | U32: RHIPSALIS MIX - T17 planta colganta | V32: 83612 | W32: https://drive.google.com/uc?export=view&id=1HMPt7u6wRyq_7yXxw94RmWmhwr-9paUV
M33: =IF(E33<>"", E33 - SUM(G33:L33), "") | O33: =IF(AND(F33<>"", E33<>""), F33*E33, "")
M34: =IF(E34<>"", E34 - SUM(G34:L34), "") | O34: =IF(AND(F34<>"", E34<>""), F34*E34, "")
M35: =IF(E35<>"", E35 - SUM(G35:L35), "") | O35: =IF(AND(F35<>"", E35<>""), F35*E35, "")
M36: =IF(E36<>"", E36 - SUM(G36:L36), "") | O36: =IF(AND(F36<>"", E36<>""), F36*E36, "")
M37: =IF(E37<>"", E37 - SUM(G37:L37), "") | O37: =IF(AND(F37<>"", E37<>""), F37*E37, "")
M38: =IF(E38<>"", E38 - SUM(G38:L38), "") | O38: =IF(AND(F38<>"", E38<>""), F38*E38, "")
M39: =IF(E39<>"", E39 - SUM(G39:L39), "") | O39: =IF(AND(F39<>"", E39<>""), F39*E39, "")
M40: =IF(E40<>"", E40 - SUM(G40:L40), "") | O40: =IF(AND(F40<>"", E40<>""), F40*E40, "")
...

Sheet Muntaner
A1: M | B1: =VLOOKUP(A1, Lookup!B:C, 2, FALSE) -> Muntaner | D1: послали пачек | E1: ='Закупка'!F1 -> внтури пачки штук? | F1: послали штук товара | G1: ИМЯ флориста написать | J1: расхождение
A2: =MATCH(A1, 'Закупка'!G1:K1, 0) -> 1 | B2: ='Закупка'!B2 -> 45845 | G2: приехало пачек | H2: реально штук товара | I2: коментарий | K2: ='Закупка'!T1 -> Holded артикул | L2: ='Закупка'!U1 -> название с holded | M2: ='Закупка'!V1 -> codigo de fabricasion
A3: ='Закупка'!A3 | B3: ='Закупка'!B3 -> Фактура 1 | C3: ='Закупка'!R3 | D3: {=INDEX('Закупка'!G3:K3, $A$2)} | E3: ='Закупка'!F3 | F3: =IF(D3<>"",D3*E3,) | K3: ='Закупка'!T3 | L3: ='Закупка'!U3 | M3: ='Закупка'!V3
A4: ='Закупка'!A4 -> 1.1 | B4: ='Закупка'!B4 -> RANUNCULUS CLOONEY TUAREQ | C4: ='Закупка'!R4 | D4: {=INDEX('Закупка'!G4:K4, $A$2)} | E4: ='Закупка'!F4 -> 10 | F4: =IF(D4<>"",D4*E4,) | K4: ='Закупка'!T4 -> 8400518 | L4: ='Закупка'!U4 -> RANUNCULUS - Butterfly - flor | M4: ='Закупка'!V4 -> RANUBUBL, RANUBUSA, 174946, 147132, 126830
A5: ='Закупка'!A5 -> 1.2 | B5: ='Закупка'!B5 -> RANUNCULUS CLOONEY GRAND PASTEL | C5: ='Закупка'!R5 | D5: {=INDEX('Закупка'!G5:K5, $A$2)} | E5: ='Закупка'!F5 -> 10 | F5: =IF(D5<>"",D5*E5,) | K5: ='Закупка'!T5 -> 8400518 | L5: ='Закупка'!U5 -> RANUNCULUS - Butterfly - flor | M5: ='Закупка'!V5 -> RANUBUBL, RANUBUSA, 174946, 147132, 126830
A6: ='Закупка'!A6 -> 1.3 | B6: ='Закупка'!B6 -> ALSTROEMERIA SI SOFIENA | C6: ='Закупка'!R6 | D6: {=INDEX('Закупка'!G6:K6, $A$2)} | E6: ='Закупка'!F6 -> 10 | F6: =IF(D6<>"",D6*E6,) | K6: ='Закупка'!T6 -> 8400154 | L6: ='Закупка'!U6 -> ALSTROEMERIA - flor | M6: ='Закупка'!V6 -> 00027, 11920, 146548, 148465, ALS VA, 148462, 148466, 11920, ALS-P, 137896, 137077, 137894, 148289, 148469, ALSTROEMERIES ALSTROEMERIA, ALSP, 11920
A7: ='Закупка'!A7 -> 1.4 | B7: ='Закупка'!B7 -> ROSA LARGE BELLE ROSE | C7: ='Закупка'!R7 | D7: {=INDEX('Закупка'!G7:K7, $A$2)} | E7: ='Закупка'!F7 -> 10 | F7: =IF(D7<>"",D7*E7,) | K7: ='Закупка'!T7 -> 8400731 | L7: ='Закупка'!U7 -> RS ROSA LA BELLE LOLOMARIK - flor | M7: ='Закупка'!V7 -> 181496
A8: ='Закупка'!A8 -> 1.5 | B8: ='Закупка'!B8 -> ROSA GARDEN PRISCILLA! | C8: ='Закупка'!R8 | D8: {=INDEX('Закупка'!G8:K8, $A$2)} | E8: ='Закупка'!F8 -> 5 | F8: =IF(D8<>"",D8*E8,) | K8: ='Закупка'!T8 -> 84001081 | L8: ='Закупка'!U8 -> ROSA PRISCILLA - flor | M8: ='Закупка'!V8
A9: ='Закупка'!A9 -> 1.6 | B9: ='Закупка'!B9 -> ROSA GARDEN MIX UHURU | C9: ='Закупка'!R9 | D9: {=INDEX('Закупка'!G9:K9, $A$2)} | E9: ='Закупка'!F9 -> 6 | F9: =IF(D9<>"",D9*E9,) | K9: ='Закупка'!T9 -> 84001157 | L9: ='Закупка'!U9 -> RISA GARDAN MIX - flor/3 | M9: ='Закупка'!V9
A10: ='Закупка'!A10 -> 1.7 | B10: ='Закупка'!B10 -> ROSA SPRAY CHIMO | C10: ='Закупка'!R10 | D10: {=INDEX('Закупка'!G10:K10, $A$2)} | E10: ='Закупка'!F10 -> 10 | F10: =IF(D10<>"",D10*E10,) | K10: ='Закупка'!T10 -> 8400828 | L10: ='Закупка'!U10 -> ROSA CHIMO - flor | M10: ='Закупка'!V10 -> 135409
A11: ='Закупка'!A11 -> 1.8 | B11: ='Закупка'!B11 -> ROSA SPRAY BIRDS NEST+ | C11: ='Закупка'!R11 | D11: {=INDEX('Закупка'!G11:K11, $A$2)} | E11: ='Закупка'!F11 -> 10 | F11: =IF(D11<>"",D11*E11,) | K11: ='Закупка'!T11 -> 84001078 | L11: ='Закупка'!U11 -> ROSA BIRDS NEST - flor | M11: ='Закупка'!V11
A12: ='Закупка'!A12 -> 1.9 | B12: ='Закупка'!B12 -> ROSA LARGE CELEB | C12: ='Закупка'!R12 | D12: {=INDEX('Закупка'!G12:K12, $A$2)} | E12: ='Закупка'!F12 -> 10 | F12: =IF(D12<>"",D12*E12,) | K12: ='Закупка'!T12 -> 84001044 | L12: ='Закупка'!U12 -> ROSA CELEBRATING HEATHER - flor | M12: ='Закупка'!V12
A13: ='Закупка'!A13 -> 1.10 | B13: ='Закупка'!B13 -> ARR CACTUS | C13: ='Закупка'!R13 | D13: {=INDEX('Закупка'!G13:K13, $A$2)} | E13: ='Закупка'!F13 -> 1 | F13: =IF(D13<>"",D13*E13,) | K13: ='Закупка'!T13 -> 8400594 | L13: ='Закупка'!U13 -> CACTUS - planta/22 | M13: ='Закупка'!V13 -> TEST 13 cactus
A14: ='Закупка'!A14 -> 1.11 | B14: ='Закупка'!B14 -> ALOE ARBO | C14: ='Закупка'!R14 | D14: {=INDEX('Закупка'!G14:K14, $A$2)} | E14: ='Закупка'!F14 -> 1 | F14: =IF(D14<>"",D14*E14,) | K14: ='Закупка'!T14 -> 84001156 | L14: ='Закупка'!U14 -> ALOE ARBO - planta/67 | M14: ='Закупка'!V14
... A97: ='Закупка'!A97 | B97: ='Закупка'!B97 | C97: ='Закупка'!R97 | D97: {=INDEX('Закупка'!G97:K97, $A$2)} | E97: ='Закупка'!F97 | F97: =IF(D97<>"",D97*E97,) | K97: ='Закупка'!T97 | L97: ='Закупка'!U97 | M97: ='Закупка'!V97
A98: ='Закупка'!A98 | B98: ='Закупка'!B98 | C98: ='Закупка'!R98 | D98: {=INDEX('Закупка'!G98:K98, $A$2)} | E98: ='Закупка'!F98 | F98: =IF(D98<>"",D98*E98,) | J98: =IF(H98<>"", H98-F98,) | K98: ='Закупка'!T98 | L98: ='Закупка'!U98 | M98: ='Закупка'!V98
A99: ='Закупка'!A99 | B99: ='Закупка'!B99 | C99: ='Закупка'!R99 | D99: {=INDEX('Закупка'!G99:K99, $A$2)} | E99: ='Закупка'!F99 | F99: =IF(D99<>"",D99*E99,) | J99: =IF(H99<>"", H99-F99,) | K99: ='Закупка'!T99 | L99: ='Закупка'!U99 | M99: ='Закупка'!V99
A100: ='Закупка'!A100 | B100: ='Закупка'!B100 | C100: ='Закупка'!R100 | D100: {=INDEX('Закупка'!G100:K100, $A$2)} | E100: ='Закупка'!F100 | F100: =IF(D100<>"",D100*E100,) | J100: =IF(H100<>"", H100-F100,) | K100: ='Закупка'!T100 | L100: ='Закупка'!U100 | M100: ='Закупка'!V100
A101: ='Закупка'!A101 | B101: ='Закупка'!B101 | C101: ='Закупка'!R101 | D101: {=INDEX('Закупка'!G101:K101, $A$2)} | E101: ='Закупка'!F101 | F101: =IF(D101<>"",D101*E101,) | J101: =IF(H101<>"", H101-F101,) | K101: ='Закупка'!T101 | L101: ='Закупка'!U101 | M101: ='Закупка'!V101
A102: ='Закупка'!A102 | B102: ='Закупка'!B102 | C102: ='Закупка'!R102 | D102: {=INDEX('Закупка'!G102:K102, $A$2)} | E102: ='Закупка'!F102 | F102: =IF(D102<>"",D102*E102,) | J102: =IF(H102<>"", H102-F102,) | K102: ='Закупка'!T102 | L102: ='Закупка'!U102 | M102: ='Закупка'!V102
A103: ='Закупка'!A103 | B103: ='Закупка'!B103 | C103: ='Закупка'!R103 | D103: {=INDEX('Закупка'!G103:K103, $A$2)} | E103: ='Закупка'!F103 | F103: =IF(D103<>"",D103*E103,) | J103: =IF(H103<>"", H103-F103,) | K103: ='Закупка'!T103 | L103: ='Закупка'!U103 | M103: ='Закупка'!V103
A104: ='Закупка'!A104 | B104: ='Закупка'!B104 | C104: ='Закупка'!R104 | D104: {=INDEX('Закупка'!G104:K104, $A$2)} | E104: ='Закупка'!F104 | F104: =IF(D104<>"",D104*E104,) | J104: =IF(H104<>"", H104-F104,) | K104: ='Закупка'!T104 | L104: ='Закупка'!U104 | M104: ='Закупка'!V104
A105: ='Закупка'!A105 | B105: ='Закупка'!B105 | C105: ='Закупка'!R105 | D105: {=INDEX('Закупка'!G105:K105, $A$2)} | E105: ='Закупка'!F105 | F105: =IF(D105<>"",D105*E105,) | J105: =IF(H105<>"", H105-F105,) | K105: ='Закупка'!T105 | L105: ='Закупка'!U105 | M105: ='Закупка'!V105
A106: ='Закупка'!A106 | B106: ='Закупка'!B106 | C106: ='Закупка'!R106 | D106: {=INDEX('Закупка'!G106:K106, $A$2)} | E106: ='Закупка'!F106 | F106: =IF(D106<>"",D106*E106,) | J106: =IF(H106<>"", H106-F106,) | K106: ='Закупка'!T106 | L106: ='Закупка'!U106 | M106: ='Закупка'!V106
A107: ='Закупка'!A107 | B107: ='Закупка'!B107 | C107: ='Закупка'!R107 | D107: {=INDEX('Закупка'!G107:K107, $A$2)} | E107: ='Закупка'!F107 | F107: =IF(D107<>"",D107*E107,) | J107: =IF(H107<>"", H107-F107,) | K107: ='Закупка'!T107 | L107: ='Закупка'!U107 | M107: ='Закупка'!V107
A108: ='Закупка'!A108 | B108: ='Закупка'!B108 | C108: ='Закупка'!R108 | D108: {=INDEX('Закупка'!G108:K108, $A$2)} | E108: ='Закупка'!F108 | F108: =IF(D108<>"",D108*E108,) | J108: =IF(H108<>"", H108-F108,) | K108: ='Закупка'!T108 | L108: ='Закупка'!U108 | M108: ='Закупка'!V108
A109: ='Закупка'!A109 | B109: ='Закупка'!B109 | C109: ='Закупка'!R109 | D109: {=INDEX('Закупка'!G109:K109, $A$2)} | E109: ='Закупка'!F109 | F109: =IF(D109<>"",D109*E109,) | J109: =IF(H109<>"", H109-F109,) | K109: ='Закупка'!T109 | L109: ='Закупка'!U109 | M109: ='Закупка'!V109
... A199: ='Закупка'!A199 | B199: ='Закупка'!B199 | C199: ='Закупка'!R199 | D199: {=INDEX('Закупка'!G199:K199, $A$2)} | E199: ='Закупка'!F199 | F199: =IF(D199<>"",D199*E199,) | J199: =IF(H199<>"", H199-F199,) | K199: ='Закупка'!T199 | L199: ='Закупка'!U199 | M199: ='Закупка'!V199

Sheet Plaza
A1: P | B1: =VLOOKUP(A1, Lookup!B:C, 2, FALSE) -> Plaza | D1: послали пачек | E1: ='Закупка'!F1 -> внтури пачки штук? | F1: послали штук товара | G1: ИМЯ флориста написать | J1: расхождение
A2: =MATCH(A1, 'Закупка'!G1:K1, 0) -> 2 | B2: ='Закупка'!B2 -> 45845 | G2: приехало пачек | H2: реально штук товара | I2: коментарий | K2: ='Закупка'!T1 -> Holded артикул | L2: ='Закупка'!U1 -> название с holded | M2: ='Закупка'!V1 -> codigo de fabricasion
A3: ='Закупка'!A3 | B3: ='Закупка'!B3 -> Фактура 1 | C3: ='Закупка'!R3 | D3: {=INDEX('Закупка'!G3:K3, $A$2)} | E3: ='Закупка'!F3 | F3: =IF(D3<>"",D3*E3,) | K3: ='Закупка'!T3 | L3: ='Закупка'!U3 | M3: ='Закупка'!V3
A4: ='Закупка'!A4 -> 1.1 | B4: ='Закупка'!B4 -> RANUNCULUS CLOONEY TUAREQ | C4: ='Закупка'!R4 | D4: {=INDEX('Закупка'!G4:K4, $A$2)} | E4: ='Закупка'!F4 -> 10 | F4: =IF(D4<>"",D4*E4,) | K4: ='Закупка'!T4 -> 8400518 | L4: ='Закупка'!U4 -> RANUNCULUS - Butterfly - flor | M4: ='Закупка'!V4 -> RANUBUBL, RANUBUSA, 174946, 147132, 126830
A5: ='Закупка'!A5 -> 1.2 | B5: ='Закупка'!B5 -> RANUNCULUS CLOONEY GRAND PASTEL | C5: ='Закупка'!R5 | D5: {=INDEX('Закупка'!G5:K5, $A$2)} | E5: ='Закупка'!F5 -> 10 | F5: =IF(D5<>"",D5*E5,) | K5: ='Закупка'!T5 -> 8400518 | L5: ='Закупка'!U5 -> RANUNCULUS - Butterfly - flor | M5: ='Закупка'!V5 -> RANUBUBL, RANUBUSA, 174946, 147132, 126830
A6: ='Закупка'!A6 -> 1.3 | B6: ='Закупка'!B6 -> ALSTROEMERIA SI SOFIENA | C6: ='Закупка'!R6 | D6: {=INDEX('Закупка'!G6:K6, $A$2)} -> 2 | E6: ='Закупка'!F6 -> 10 | F6: =IF(D6<>"",D6*E6,) -> 20 | G6: 2 | H6: 20 | K6: ='Закупка'!T6 -> 8400154 | L6: ='Закупка'!U6 -> ALSTROEMERIA - flor | M6: ='Закупка'!V6 -> 00027, 11920, 146548, 148465, ALS VA, 148462, 148466, 11920, ALS-P, 137896, 137077, 137894, 148289, 148469, ALSTROEMERIES ALSTROEMERIA, ALSP, 11920
A7: ='Закупка'!A7 -> 1.4 | B7: ='Закупка'!B7 -> ROSA LARGE BELLE ROSE | C7: ='Закупка'!R7 | D7: {=INDEX('Закупка'!G7:K7, $A$2)} | E7: ='Закупка'!F7 -> 10 | F7: =IF(D7<>"",D7*E7,) | K7: ='Закупка'!T7 -> 8400731 | L7: ='Закупка'!U7 -> RS ROSA LA BELLE LOLOMARIK - flor | M7: ='Закупка'!V7 -> 181496
A8: ='Закупка'!A8 -> 1.5 | B8: ='Закупка'!B8 -> ROSA GARDEN PRISCILLA! | C8: ='Закупка'!R8 | D8: {=INDEX('Закупка'!G8:K8, $A$2)} | E8: ='Закупка'!F8 -> 5 | F8: =IF(D8<>"",D8*E8,) | K8: ='Закупка'!T8 -> 84001081 | L8: ='Закупка'!U8 -> ROSA PRISCILLA - flor | M8: ='Закупка'!V8
A9: ='Закупка'!A9 -> 1.6 | B9: ='Закупка'!B9 -> ROSA GARDEN MIX UHURU | C9: ='Закупка'!R9 | D9: {=INDEX('Закупка'!G9:K9, $A$2)} | E9: ='Закупка'!F9 -> 6 | F9: =IF(D9<>"",D9*E9,) | K9: ='Закупка'!T9 -> 84001157 | L9: ='Закупка'!U9 -> RISA GARDAN MIX - flor/3 | M9: ='Закупка'!V9
A10: ='Закупка'!A10 -> 1.7 | B10: ='Закупка'!B10 -> ROSA SPRAY CHIMO | C10: ='Закупка'!R10 | D10: {=INDEX('Закупка'!G10:K10, $A$2)} -> 2 | E10: ='Закупка'!F10 -> 10 | F10: =IF(D10<>"",D10*E10,) -> 20 | G10: 2 | H10: 20 | K10: ='Закупка'!T10 -> 8400828 | L10: ='Закупка'!U10 -> ROSA CHIMO - flor | M10: ='Закупка'!V10 -> 135409
A11: ='Закупка'!A11 -> 1.8 | B11: ='Закупка'!B11 -> ROSA SPRAY BIRDS NEST+ | C11: ='Закупка'!R11 | D11: {=INDEX('Закупка'!G11:K11, $A$2)} | E11: ='Закупка'!F11 -> 10 | F11: =IF(D11<>"",D11*E11,) | K11: ='Закупка'!T11 -> 84001078 | L11: ='Закупка'!U11 -> ROSA BIRDS NEST - flor | M11: ='Закупка'!V11
A12: ='Закупка'!A12 -> 1.9 | B12: ='Закупка'!B12 -> ROSA LARGE CELEB | C12: ='Закупка'!R12 | D12: {=INDEX('Закупка'!G12:K12, $A$2)} -> 3 | E12: ='Закупка'!F12 -> 10 | F12: =IF(D12<>"",D12*E12,) -> 30 | G12: 3 | H12: 30 | K12: ='Закупка'!T12 -> 84001044 | L12: ='Закупка'!U12 -> ROSA CELEBRATING HEATHER - flor | M12: ='Закупка'!V12
A13: ='Закупка'!A13 -> 1.10 | B13: ='Закупка'!B13 -> ARR CACTUS | C13: ='Закупка'!R13 | D13: {=INDEX('Закупка'!G13:K13, $A$2)} | E13: ='Закупка'!F13 -> 1 | F13: =IF(D13<>"",D13*E13,) | K13: ='Закупка'!T13 -> 8400594 | L13: ='Закупка'!U13 -> CACTUS - planta/22 | M13: ='Закупка'!V13 -> TEST 13 cactus
A14: ='Закупка'!A14 -> 1.11 | B14: ='Закупка'!B14 -> ALOE ARBO | C14: ='Закупка'!R14 | D14: {=INDEX('Закупка'!G14:K14, $A$2)} | E14: ='Закупка'!F14 -> 1 | F14: =IF(D14<>"",D14*E14,) | K14: ='Закупка'!T14 -> 84001156 | L14: ='Закупка'!U14 -> ALOE ARBO - planta/67 | M14: ='Закупка'!V14
A15: ='Закупка'!A15 -> 1.12 | B15: ='Закупка'!B15 -> ALOE ARBO | C15: ='Закупка'!R15 | D15: {=INDEX('Закупка'!G15:K15, $A$2)} | E15: ='Закупка'!F15 -> 1 | F15: =IF(D15<>"",D15*E15,) | K15: ='Закупка'!T15 -> 84001155 | L15: ='Закупка'!U15 -> ALOE ARBO - planta/47 | M15: ='Закупка'!V15
A16: ='Закупка'!A16 -> 1.13 | B16: ='Закупка'!B16 -> ARR2 MB GROEN IJZER REK 1 BOL | C16: ='Закупка'!R16 | D16: {=INDEX('Закупка'!G16:K16, $A$2)} | E16: ='Закупка'!F16 -> 1 | F16: =IF(D16<>"",D16*E16,) | K16: ='Закупка'!T16 -> 8400410 | L16: ='Закупка'!U16 -> SUCCULENTUS T16, T22 - MIX - planta/22 | M16: ='Закупка'!V16 -> 6CRASA22, 54, CRASS16
A17: ='Закупка'!A17 -> 1.14 | B17: ='Закупка'!B17 -> ARR NARCISSUS TETE-A-TETE | C17: ='Закупка'!R17 | D17: {=INDEX('Закупка'!G17:K17, $A$2)} | E17: ='Закупка'!F17 -> 1 | F17: =IF(D17<>"",D17*E17,) | K17: ='Закупка'!T17 -> 84001152 | L17: ='Закупка'!U17 -> NARCISO TETE-A-TETE - composición/14 | M17: ='Закупка'!V17
A18: ='Закупка'!A18 -> 1.15 | B18: ='Закупка'!B18 -> ARR NARCISSUS | C18: ='Закупка'!R18 | D18: {=INDEX('Закупка'!G18:K18, $A$2)} | E18: ='Закупка'!F18 -> 1 | F18: =IF(D18<>"",D18*E18,) | K18: ='Закупка'!T18 -> 84001038 | L18: ='Закупка'!U18 -> NARCIS MASCOTA - planta /17 | M18: ='Закупка'!V18
A19: ='Закупка'!A19 -> 1.16 | B19: ='Закупка'!B19 -> ARR2 PL KER BAROK DRACENA | C19: ='Закупка'!R19 | D19: {=INDEX('Закупка'!G19:K19, $A$2)} | E19: ='Закупка'!F19 -> 1 | F19: =IF(D19<>"",D19*E19,) | K19: ='Закупка'!T19 -> 84001154 | L19: ='Закупка'!U19 -> COMPOSITION DE DRECENA - planta/38 | M19: ='Закупка'!V19
A20: ='Закупка'!A20 -> 1.17 | B20: ='Закупка'!B20 -> ARR2 PL KER BAROK DRACENA | C20: ='Закупка'!R20 | D20: {=INDEX('Закупка'!G20:K20, $A$2)} | E20: ='Закупка'!F20 -> 1 | F20: =IF(D20<>"",D20*E20,) | K20: ='Закупка'!T20 -> 84001154 | L20: ='Закупка'!U20 -> COMPOSITION DE DRECENA - planta/38 | M20: ='Закупка'!V20
A21: ='Закупка'!A21 -> 1.18 | B21: ='Закупка'!B21 -> ARR2 PL GLAS CILINDER PHAL PAARS | C21: ='Закупка'!R21 | D21: {=INDEX('Закупка'!G21:K21, $A$2)} | E21: ='Закупка'!F21 -> 1 | F21: =IF(D21<>"",D21*E21,) | K21: ='Закупка'!T21 -> 84001153 | L21: ='Закупка'!U21 -> ARRANGEMENT DE PHALAENOPSIS - composición/56 | M21: ='Закупка'!V21
A22: ='Закупка'!A22 -> 1.19 | B22: ='Закупка'!B22 -> CRASSULA OVATA | C22: ='Закупка'!R22 | D22: {=INDEX('Закупка'!G22:K22, $A$2)} | E22: ='Закупка'!F22 -> 1 | F22: =IF(D22<>"",D22*E22,) | K22: ='Закупка'!T22 -> 8400365 | L22: ='Закупка'!U22 -> ARBOL DE JADE T25 -planta/120 | M22: ='Закупка'!V22 -> ARBOL DE JADE GRANDE (Crassula Ovata) T-25
A23: ='Закупка'!A23 -> 1.20 | B23: ='Закупка'!B23 -> CRASSULA OVATA | C23: ='Закупка'!R23 | D23: {=INDEX('Закупка'!G23:K23, $A$2)} | E23: ='Закупка'!F23 -> 1 | F23: =IF(D23<>"",D23*E23,) | K23: ='Закупка'!T23 -> 8400365 | L23: ='Закупка'!U23 -> ARBOL DE JADE T25 -planta/188 | M23: ='Закупка'!V23 -> ARBOL DE JADE GRANDE (Crassula Ovata) T-25
A24: ='Закупка'!A24 -> 1.21 | B24: ='Закупка'!B24 -> CODIAEUM VARI MRS ICETON | C24: ='Закупка'!R24 | D24: {=INDEX('Закупка'!G24:K24, $A$2)} | E24: ='Закупка'!F24 -> 1 | F24: =IF(D24<>"",D24*E24,) | K24: ='Закупка'!T24 -> 8400558 | L24: ='Закупка'!U24 -> CROTON 50cm - Petra - planta/36 | M24: ='Закупка'!V24 -> 81945, CROMA20
... A100: ='Закупка'!A100 | B100: ='Закупка'!B100 | C100: ='Закупка'!R100 | D100: {=INDEX('Закупка'!G100:K100, $A$2)} | E100: ='Закупка'!F100 | F100: =IF(D100<>"",D100*E100,) | K100: ='Закупка'!T100 | L100: ='Закупка'!U100 | M100: ='Закупка'!V100
A101: ='Закупка'!A101 | B101: ='Закупка'!B101 | C101: ='Закупка'!R101 | D101: {=INDEX('Закупка'!G101:K101, $A$2)} | E101: ='Закупка'!F101 | F101: =IF(D101<>"",D101*E101,) | J101: =IF(H101<>"", H101-F101,) | K101: ='Закупка'!T101 | L101: ='Закупка'!U101 | M101: ='Закупка'!V101
A102: ='Закупка'!A102 | B102: ='Закупка'!B102 | C102: ='Закупка'!R102 | D102: {=INDEX('Закупка'!G102:K102, $A$2)} | E102: ='Закупка'!F102 | F102: =IF(D102<>"",D102*E102,) | J102: =IF(H102<>"", H102-F102,) | K102: ='Закупка'!T102 | L102: ='Закупка'!U102 | M102: ='Закупка'!V102
A103: ='Закупка'!A103 | B103: ='Закупка'!B103 | C103: ='Закупка'!R103 | D103: {=INDEX('Закупка'!G103:K103, $A$2)} | E103: ='Закупка'!F103 | F103: =IF(D103<>"",D103*E103,) | J103: =IF(H103<>"", H103-F103,) | K103: ='Закупка'!T103 | L103: ='Закупка'!U103 | M103: ='Закупка'!V103
A104: ='Закупка'!A104 | B104: ='Закупка'!B104 | C104: ='Закупка'!R104 | D104: {=INDEX('Закупка'!G104:K104, $A$2)} | E104: ='Закупка'!F104 | F104: =IF(D104<>"",D104*E104,) | J104: =IF(H104<>"", H104-F104,) | K104: ='Закупка'!T104 | L104: ='Закупка'!U104 | M104: ='Закупка'!V104
A105: ='Закупка'!A105 | B105: ='Закупка'!B105 | C105: ='Закупка'!R105 | D105: {=INDEX('Закупка'!G105:K105, $A$2)} | E105: ='Закупка'!F105 | F105: =IF(D105<>"",D105*E105,) | J105: =IF(H105<>"", H105-F105,) | K105: ='Закупка'!T105 | L105: ='Закупка'!U105 | M105: ='Закупка'!V105
A106: ='Закупка'!A106 | B106: ='Закупка'!B106 | C106: ='Закупка'!R106 | D106: {=INDEX('Закупка'!G106:K106, $A$2)} | E106: ='Закупка'!F106 | F106: =IF(D106<>"",D106*E106,) | J106: =IF(H106<>"", H106-F106,) | K106: ='Закупка'!T106 | L106: ='Закупка'!U106 | M106: ='Закупка'!V106
A107: ='Закупка'!A107 | B107: ='Закупка'!B107 | C107: ='Закупка'!R107 | D107: {=INDEX('Закупка'!G107:K107, $A$2)} | E107: ='Закупка'!F107 | F107: =IF(D107<>"",D107*E107,) | J107: =IF(H107<>"", H107-F107,) | K107: ='Закупка'!T107 | L107: ='Закупка'!U107 | M107: ='Закупка'!V107
A108: ='Закупка'!A108 | B108: ='Закупка'!B108 | C108: ='Закупка'!R108 | D108: {=INDEX('Закупка'!G108:K108, $A$2)} | E108: ='Закупка'!F108 | F108: =IF(D108<>"",D108*E108,) | J108: =IF(H108<>"", H108-F108,) | K108: ='Закупка'!T108 | L108: ='Закупка'!U108 | M108: ='Закупка'!V108
A109: ='Закупка'!A109 | B109: ='Закупка'!B109 | C109: ='Закупка'!R109 | D109: {=INDEX('Закупка'!G109:K109, $A$2)} | E109: ='Закупка'!F109 | F109: =IF(D109<>"",D109*E109,) | J109: =IF(H109<>"", H109-F109,) | K109: ='Закупка'!T109 | L109: ='Закупка'!U109 | M109: ='Закупка'!V109
A110: ='Закупка'!A110 | B110: ='Закупка'!B110 | C110: ='Закупка'!R110 | D110: {=INDEX('Закупка'!G110:K110, $A$2)} | E110: ='Закупка'!F110 | F110: =IF(D110<>"",D110*E110,) | J110: =IF(H110<>"", H110-F110,) | K110: ='Закупка'!T110 | L110: ='Закупка'!U110 | M110: ='Закупка'!V110
A111: ='Закупка'!A111 | B111: ='Закупка'!B111 | C111: ='Закупка'!R111 | D111: {=INDEX('Закупка'!G111:K111, $A$2)} | E111: ='Закупка'!F111 | F111: =IF(D111<>"",D111*E111,) | J111: =IF(H111<>"", H111-F111,) | K111: ='Закупка'!T111 | L111: ='Закупка'!U111 | M111: ='Закупка'!V111
A112: ='Закупка'!A112 | B112: ='Закупка'!B112 | C112: ='Закупка'!R112 | D112: {=INDEX('Закупка'!G112:K112, $A$2)} | E112: ='Закупка'!F112 | F112: =IF(D112<>"",D112*E112,) | J112: =IF(H112<>"", H112-F112,) | K112: ='Закупка'!T112 | L112: ='Закупка'!U112 | M112: ='Закупка'!V112
... A199: ='Закупка'!A199 | B199: ='Закупка'!B199 | C199: ='Закупка'!R199 | D199: {=INDEX('Закупка'!G199:K199, $A$2)} | E199: ='Закупка'!F199 | F199: =IF(D199<>"",D199*E199,) | J199: =IF(H199<>"", H199-F199,) | K199: ='Закупка'!T199 | L199: ='Закупка'!U199 | M199: ='Закупка'!V199

Sheet Augusta
A1: A | B1: =VLOOKUP(A1, Lookup!B:C, 2, FALSE) -> Augusta | D1: послали пачек | E1: ='Закупка'!F1 -> внтури пачки штук? | F1: послали штук товара | G1: ИМЯ флориста написать | J1: расхождение
A2: =MATCH(A1, 'Закупка'!G1:K1, 0) -> 3 | B2: ='Закупка'!B2 -> 45845 | G2: приехало пачек | H2: реально штук товара | I2: коментарий | K2: ='Закупка'!T1 -> Holded артикул | L2: ='Закупка'!U1 -> название с holded | M2: ='Закупка'!V1 -> codigo de fabricasion
A3: ='Закупка'!A3 | B3: ='Закупка'!B3 -> Фактура 1 | C3: ='Закупка'!R3 | D3: {=INDEX('Закупка'!G3:K3, $A$2)} | E3: ='Закупка'!F3 | F3: =IF(D3<>"",D3*E3,) | K3: ='Закупка'!T3 | L3: ='Закупка'!U3 | M3: ='Закупка'!V3
A4: ='Закупка'!A4 -> 1.1 | B4: ='Закупка'!B4 -> RANUNCULUS CLOONEY TUAREQ | C4: ='Закупка'!R4 | D4: {=INDEX('Закупка'!G4:K4, $A$2)} | E4: ='Закупка'!F4 -> 10 | F4: =IF(D4<>"",D4*E4,) | K4: ='Закупка'!T4 -> 8400518 | L4: ='Закупка'!U4 -> RANUNCULUS - Butterfly - flor | M4: ='Закупка'!V4 -> RANUBUBL, RANUBUSA, 174946, 147132, 126830
A5: ='Закупка'!A5 -> 1.2 | B5: ='Закупка'!B5 -> RANUNCULUS CLOONEY GRAND PASTEL | C5: ='Закупка'!R5 | D5: {=INDEX('Закупка'!G5:K5, $A$2)} | E5: ='Закупка'!F5 -> 10 | F5: =IF(D5<>"",D5*E5,) | K5: ='Закупка'!T5 -> 8400518 | L5: ='Закупка'!U5 -> RANUNCULUS - Butterfly - flor | M5: ='Закупка'!V5 -> RANUBUBL, RANUBUSA, 174946, 147132, 126830
A6: ='Закупка'!A6 -> 1.3 | B6: ='Закупка'!B6 -> ALSTROEMERIA SI SOFIENA | C6: ='Закупка'!R6 | D6: {=INDEX('Закупка'!G6:K6, $A$2)} | E6: ='Закупка'!F6 -> 10 | F6: =IF(D6<>"",D6*E6,) | K6: ='Закупка'!T6 -> 8400154 | L6: ='Закупка'!U6 -> ALSTROEMERIA - flor | M6: ='Закупка'!V6 -> 00027, 11920, 146548, 148465, ALS VA, 148462, 148466, 11920, ALS-P, 137896, 137077, 137894, 148289, 148469, ALSTROEMERIES ALSTROEMERIA, ALSP, 11920
A7: ='Закупка'!A7 -> 1.4 | B7: ='Закупка'!B7 -> ROSA LARGE BELLE ROSE | C7: ='Закупка'!R7 | D7: {=INDEX('Закупка'!G7:K7, $A$2)} | E7: ='Закупка'!F7 -> 10 | F7: =IF(D7<>"",D7*E7,) | K7: ='Закупка'!T7 -> 8400731 | L7: ='Закупка'!U7 -> RS ROSA LA BELLE LOLOMARIK - flor | M7: ='Закупка'!V7 -> 181496
A8: ='Закупка'!A8 -> 1.5 | B8: ='Закупка'!B8 -> ROSA GARDEN PRISCILLA! | C8: ='Закупка'!R8 | D8: {=INDEX('Закупка'!G8:K8, $A$2)} | E8: ='Закупка'!F8 -> 5 | F8: =IF(D8<>"",D8*E8,) | K8: ='Закупка'!T8 -> 84001081 | L8: ='Закупка'!U8 -> ROSA PRISCILLA - flor | M8: ='Закупка'!V8
A9: ='Закупка'!A9 -> 1.6 | B9: ='Закупка'!B9 -> ROSA GARDEN MIX UHURU | C9: ='Закупка'!R9 | D9: {=INDEX('Закупка'!G9:K9, $A$2)} | E9: ='Закупка'!F9 -> 6 | F9: =IF(D9<>"",D9*E9,) | K9: ='Закупка'!T9 -> 84001157 | L9: ='Закупка'!U9 -> RISA GARDAN MIX - flor/3 | M9: ='Закупка'!V9
A10: ='Закупка'!A10 -> 1.7 | B10: ='Закупка'!B10 -> ROSA SPRAY CHIMO | C10: ='Закупка'!R10 | D10: {=INDEX('Закупка'!G10:K10, $A$2)} | E10: ='Закупка'!F10 -> 10 | F10: =IF(D10<>"",D10*E10,) | K10: ='Закупка'!T10 -> 8400828 | L10: ='Закупка'!U10 -> ROSA CHIMO - flor | M10: ='Закупка'!V10 -> 135409
A11: ='Закупка'!A11 -> 1.8 | B11: ='Закупка'!B11 -> ROSA SPRAY BIRDS NEST+ | C11: ='Закупка'!R11 | D11: {=INDEX('Закупка'!G11:K11, $A$2)} | E11: ='Закупка'!F11 -> 10 | F11: =IF(D11<>"",D11*E11,) | K11: ='Закупка'!T11 -> 84001078 | L11: ='Закупка'!U11 -> ROSA BIRDS NEST - flor | M11: ='Закупка'!V11
A12: ='Закупка'!A12 -> 1.9 | B12: ='Закупка'!B12 -> ROSA LARGE CELEB | C12: ='Закупка'!R12 | D12: {=INDEX('Закупка'!G12:K12, $A$2)} | E12: ='Закупка'!F12 -> 10 | F12: =IF(D12<>"",D12*E12,) | K12: ='Закупка'!T12 -> 84001044 | L12: ='Закупка'!U12 -> ROSA CELEBRATING HEATHER - flor | M12: ='Закупка'!V12
A13: ='Закупка'!A13 -> 1.10 | B13: ='Закупка'!B13 -> ARR CACTUS | C13: ='Закупка'!R13 | D13: {=INDEX('Закупка'!G13:K13, $A$2)} | E13: ='Закупка'!F13 -> 1 | F13: =IF(D13<>"",D13*E13,) | K13: ='Закупка'!T13 -> 8400594 | L13: ='Закупка'!U13 -> CACTUS - planta/22 | M13: ='Закупка'!V13 -> TEST 13 cactus
A14: ='Закупка'!A14 -> 1.11 | B14: ='Закупка'!B14 -> ALOE ARBO | C14: ='Закупка'!R14 | D14: {=INDEX('Закупка'!G14:K14, $A$2)} | E14: ='Закупка'!F14 -> 1 | F14: =IF(D14<>"",D14*E14,) | K14: ='Закупка'!T14 -> 84001156 | L14: ='Закупка'!U14 -> ALOE ARBO - planta/67 | M14: ='Закупка'!V14
... A98: ='Закупка'!A98 | B98: ='Закупка'!B98 | C98: ='Закупка'!R98 | D98: {=INDEX('Закупка'!G98:K98, $A$2)} | E98: ='Закупка'!F98 | F98: =IF(D98<>"",D98*E98,) | K98: ='Закупка'!T98 | L98: ='Закупка'!U98 | M98: ='Закупка'!V98
A99: ='Закупка'!A99 | B99: ='Закупка'!B99 | C99: ='Закупка'!R99 | D99: {=INDEX('Закупка'!G99:K99, $A$2)} | E99: ='Закупка'!F99 | F99: =IF(D99<>"",D99*E99,) | J99: =IF(H99<>"", H99-F99,) | K99: ='Закупка'!T99 | L99: ='Закупка'!U99 | M99: ='Закупка'!V99
A100: ='Закупка'!A100 | B100: ='Закупка'!B100 | C100: ='Закупка'!R100 | D100: {=INDEX('Закупка'!G100:K100, $A$2)} | E100: ='Закупка'!F100 | F100: =IF(D100<>"",D100*E100,) | J100: =IF(H100<>"", H100-F100,) | K100: ='Закупка'!T100 | L100: ='Закупка'!U100 | M100: ='Закупка'!V100
A101: ='Закупка'!A101 | B101: ='Закупка'!B101 | C101: ='Закупка'!R101 | D101: {=INDEX('Закупка'!G101:K101, $A$2)} | E101: ='Закупка'!F101 | F101: =IF(D101<>"",D101*E101,) | J101: =IF(H101<>"", H101-F101,) | K101: ='Закупка'!T101 | L101: ='Закупка'!U101 | M101: ='Закупка'!V101
A102: ='Закупка'!A102 | B102: ='Закупка'!B102 | C102: ='Закупка'!R102 | D102: {=INDEX('Закупка'!G102:K102, $A$2)} | E102: ='Закупка'!F102 | F102: =IF(D102<>"",D102*E102,) | J102: =IF(H102<>"", H102-F102,) | K102: ='Закупка'!T102 | L102: ='Закупка'!U102 | M102: ='Закупка'!V102
A103: ='Закупка'!A103 | B103: ='Закупка'!B103 | C103: ='Закупка'!R103 | D103: {=INDEX('Закупка'!G103:K103, $A$2)} | E103: ='Закупка'!F103 | F103: =IF(D103<>"",D103*E103,) | J103: =IF(H103<>"", H103-F103,) | K103: ='Закупка'!T103 | L103: ='Закупка'!U103 | M103: ='Закупка'!V103
A104: ='Закупка'!A104 | B104: ='Закупка'!B104 | C104: ='Закупка'!R104 | D104: {=INDEX('Закупка'!G104:K104, $A$2)} | E104: ='Закупка'!F104 | F104: =IF(D104<>"",D104*E104,) | J104: =IF(H104<>"", H104-F104,) | K104: ='Закупка'!T104 | L104: ='Закупка'!U104 | M104: ='Закупка'!V104
A105: ='Закупка'!A105 | B105: ='Закупка'!B105 | C105: ='Закупка'!R105 | D105: {=INDEX('Закупка'!G105:K105, $A$2)} | E105: ='Закупка'!F105 | F105: =IF(D105<>"",D105*E105,) | J105: =IF(H105<>"", H105-F105,) | K105: ='Закупка'!T105 | L105: ='Закупка'!U105 | M105: ='Закупка'!V105
A106: ='Закупка'!A106 | B106: ='Закупка'!B106 | C106: ='Закупка'!R106 | D106: {=INDEX('Закупка'!G106:K106, $A$2)} | E106: ='Закупка'!F106 | F106: =IF(D106<>"",D106*E106,) | J106: =IF(H106<>"", H106-F106,) | K106: ='Закупка'!T106 | L106: ='Закупка'!U106 | M106: ='Закупка'!V106
A107: ='Закупка'!A107 | B107: ='Закупка'!B107 | C107: ='Закупка'!R107 | D107: {=INDEX('Закупка'!G107:K107, $A$2)} | E107: ='Закупка'!F107 | F107: =IF(D107<>"",D107*E107,) | J107: =IF(H107<>"", H107-F107,) | K107: ='Закупка'!T107 | L107: ='Закупка'!U107 | M107: ='Закупка'!V107
A108: ='Закупка'!A108 | B108: ='Закупка'!B108 | C108: ='Закупка'!R108 | D108: {=INDEX('Закупка'!G108:K108, $A$2)} | E108: ='Закупка'!F108 | F108: =IF(D108<>"",D108*E108,) | J108: =IF(H108<>"", H108-F108,) | K108: ='Закупка'!T108 | L108: ='Закупка'!U108 | M108: ='Закупка'!V108
A109: ='Закупка'!A109 | B109: ='Закупка'!B109 | C109: ='Закупка'!R109 | D109: {=INDEX('Закупка'!G109:K109, $A$2)} | E109: ='Закупка'!F109 | F109: =IF(D109<>"",D109*E109,) | J109: =IF(H109<>"", H109-F109,) | K109: ='Закупка'!T109 | L109: ='Закупка'!U109 | M109: ='Закупка'!V109
A110: ='Закупка'!A110 | B110: ='Закупка'!B110 | C110: ='Закупка'!R110 | D110: {=INDEX('Закупка'!G110:K110, $A$2)} | E110: ='Закупка'!F110 | F110: =IF(D110<>"",D110*E110,) | J110: =IF(H110<>"", H110-F110,) | K110: ='Закупка'!T110 | L110: ='Закупка'!U110 | M110: ='Закупка'!V110
... A199: ='Закупка'!A199 | B199: ='Закупка'!B199 | C199: ='Закупка'!R199 | D199: {=INDEX('Закупка'!G199:K199, $A$2)} | E199: ='Закупка'!F199 | F199: =IF(D199<>"",D199*E199,) | J199: =IF(H199<>"", H199-F199,) | K199: ='Закупка'!T199 | L199: ='Закупка'!U199 | M199: ='Закупка'!V199

Sheet Gloria
A1: G | B1: =VLOOKUP(A1, Lookup!B:C, 2, FALSE) -> Gloria | D1: послали пачек | E1: ='Закупка'!F1 -> внтури пачки штук? | F1: послали штук товара | G1: ИМЯ флориста написать | J1: расхождение
A2: =MATCH(A1, 'Закупка'!G1:K1, 0) -> 4 | B2: ='Закупка'!B2 -> 45845 | G2: приехало пачек | H2: реально штук товара | I2: коментарий | K2: ='Закупка'!T1 -> Holded артикул | L2: ='Закупка'!U1 -> название с holded | M2: ='Закупка'!V1 -> codigo de fabricasion
A3: ='Закупка'!A3 | B3: ='Закупка'!B3 -> Фактура 1 | C3: ='Закупка'!R3 | D3: {=INDEX('Закупка'!G3:K3, $A$2)} | E3: ='Закупка'!F3 | F3: =IF(D3<>"",D3*E3,) | K3: ='Закупка'!T3 | L3: ='Закупка'!U3 | M3: ='Закупка'!V3
A4: ='Закупка'!A4 -> 1.1 | B4: ='Закупка'!B4 -> RANUNCULUS CLOONEY TUAREQ | C4: ='Закупка'!R4 | D4: {=INDEX('Закупка'!G4:K4, $A$2)} -> 3 | E4: ='Закупка'!F4 -> 10 | F4: =IF(D4<>"",D4*E4,) -> 30 | G4: 3 | H4: 30 | K4: ='Закупка'!T4 -> 8400518 | L4: ='Закупка'!U4 -> RANUNCULUS - Butterfly - flor | M4: ='Закупка'!V4 -> RANUBUBL, RANUBUSA, 174946, 147132, 126830
A5: ='Закупка'!A5 -> 1.2 | B5: ='Закупка'!B5 -> RANUNCULUS CLOONEY GRAND PASTEL | C5: ='Закупка'!R5 | D5: {=INDEX('Закупка'!G5:K5, $A$2)} | E5: ='Закупка'!F5 -> 10 | F5: =IF(D5<>"",D5*E5,) | K5: ='Закупка'!T5 -> 8400518 | L5: ='Закупка'!U5 -> RANUNCULUS - Butterfly - flor | M5: ='Закупка'!V5 -> RANUBUBL, RANUBUSA, 174946, 147132, 126830
A6: ='Закупка'!A6 -> 1.3 | B6: ='Закупка'!B6 -> ALSTROEMERIA SI SOFIENA | C6: ='Закупка'!R6 | D6: {=INDEX('Закупка'!G6:K6, $A$2)} -> 2 | E6: ='Закупка'!F6 -> 10 | F6: =IF(D6<>"",D6*E6,) -> 20 | G6: 2 | H6: 20 | K6: ='Закупка'!T6 -> 8400154 | L6: ='Закупка'!U6 -> ALSTROEMERIA - flor | M6: ='Закупка'!V6 -> 00027, 11920, 146548, 148465, ALS VA, 148462, 148466, 11920, ALS-P, 137896, 137077, 137894, 148289, 148469, ALSTROEMERIES ALSTROEMERIA, ALSP, 11920
A7: ='Закупка'!A7 -> 1.4 | B7: ='Закупка'!B7 -> ROSA LARGE BELLE ROSE | C7: ='Закупка'!R7 | D7: {=INDEX('Закупка'!G7:K7, $A$2)} | E7: ='Закупка'!F7 -> 10 | F7: =IF(D7<>"",D7*E7,) | K7: ='Закупка'!T7 -> 8400731 | L7: ='Закупка'!U7 -> RS ROSA LA BELLE LOLOMARIK - flor | M7: ='Закупка'!V7 -> 181496
A8: ='Закупка'!A8 -> 1.5 | B8: ='Закупка'!B8 -> ROSA GARDEN PRISCILLA! | C8: ='Закупка'!R8 | D8: {=INDEX('Закупка'!G8:K8, $A$2)} -> 2 | E8: ='Закупка'!F8 -> 5 | F8: =IF(D8<>"",D8*E8,) -> 10 | G8: 2 | H8: 10 | K8: ='Закупка'!T8 -> 84001081 | L8: ='Закупка'!U8 -> ROSA PRISCILLA - flor | M8: ='Закупка'!V8
A9: ='Закупка'!A9 -> 1.6 | B9: ='Закупка'!B9 -> ROSA GARDEN MIX UHURU | C9: ='Закупка'!R9 | D9: {=INDEX('Закупка'!G9:K9, $A$2)} | E9: ='Закупка'!F9 -> 6 | F9: =IF(D9<>"",D9*E9,) | K9: ='Закупка'!T9 -> 84001157 | L9: ='Закупка'!U9 -> RISA GARDAN MIX - flor/3 | M9: ='Закупка'!V9
A10: ='Закупка'!A10 -> 1.7 | B10: ='Закупка'!B10 -> ROSA SPRAY CHIMO | C10: ='Закупка'!R10 | D10: {=INDEX('Закупка'!G10:K10, $A$2)} -> 3 | E10: ='Закупка'!F10 -> 10 | F10: =IF(D10<>"",D10*E10,) -> 30 | G10: 3 | H10: 30 | K10: ='Закупка'!T10 -> 8400828 | L10: ='Закупка'!U10 -> ROSA CHIMO - flor | M10: ='Закупка'!V10 -> 135409
A11: ='Закупка'!A11 -> 1.8 | B11: ='Закупка'!B11 -> ROSA SPRAY BIRDS NEST+ | C11: ='Закупка'!R11 | D11: {=INDEX('Закупка'!G11:K11, $A$2)} -> 1 | E11: ='Закупка'!F11 -> 10 | F11: =IF(D11<>"",D11*E11,) -> 10 | G11: 1 | H11: 10 | K11: ='Закупка'!T11 -> 84001078 | L11: ='Закупка'!U11 -> ROSA BIRDS NEST - flor | M11: ='Закупка'!V11
A12: ='Закупка'!A12 -> 1.9 | B12: ='Закупка'!B12 -> ROSA LARGE CELEB | C12: ='Закупка'!R12 | D12: {=INDEX('Закупка'!G12:K12, $A$2)} -> 3 | E12: ='Закупка'!F12 -> 10 | F12: =IF(D12<>"",D12*E12,) -> 30 | G12: 3 | H12: 28 | K12: ='Закупка'!T12 -> 84001044 | L12: ='Закупка'!U12 -> ROSA CELEBRATING HEATHER - flor | M12: ='Закупка'!V12
A13: ='Закупка'!A13 -> 1.10 | B13: ='Закупка'!B13 -> ARR CACTUS | C13: ='Закупка'!R13 | D13: {=INDEX('Закупка'!G13:K13, $A$2)} -> 9 | E13: ='Закупка'!F13 -> 1 | F13: =IF(D13<>"",D13*E13,) -> 9 | G13: 1 | H13: 9 | K13: ='Закупка'!T13 -> 8400594 | L13: ='Закупка'!U13 -> CACTUS - planta/22 | M13: ='Закупка'!V13 -> TEST 13 cactus
A14: ='Закупка'!A14 -> 1.11 | B14: ='Закупка'!B14 -> ALOE ARBO | C14: ='Закупка'!R14 | D14: {=INDEX('Закупка'!G14:K14, $A$2)} -> 1 | E14: ='Закупка'!F14 -> 1 | F14: =IF(D14<>"",D14*E14,) -> 1 | G14: 1 | H14: 1 | K14: ='Закупка'!T14 -> 84001156 | L14: ='Закупка'!U14 -> ALOE ARBO - planta/67 | M14: ='Закупка'!V14
A15: ='Закупка'!A15 -> 1.12 | B15: ='Закупка'!B15 -> ALOE ARBO | C15: ='Закупка'!R15 | D15: {=INDEX('Закупка'!G15:K15, $A$2)} -> 4 | E15: ='Закупка'!F15 -> 1 | F15: =IF(D15<>"",D15*E15,) -> 4 | G15: 1 | H15: 4 | K15: ='Закупка'!T15 -> 84001155 | L15: ='Закупка'!U15 -> ALOE ARBO - planta/47 | M15: ='Закупка'!V15
A16: ='Закупка'!A16 -> 1.13 | B16: ='Закупка'!B16 -> ARR2 MB GROEN IJZER REK 1 BOL | C16: ='Закупка'!R16 | D16: {=INDEX('Закупка'!G16:K16, $A$2)} -> 4 | E16: ='Закупка'!F16 -> 1 | F16: =IF(D16<>"",D16*E16,) -> 4 | G16: 1 | H16: 4 | K16: ='Закупка'!T16 -> 8400410 | L16: ='Закупка'!U16 -> SUCCULENTUS T16, T22 - MIX - planta/22 | M16: ='Закупка'!V16 -> 6CRASA22, 54, CRASS16
A17: ='Закупка'!A17 -> 1.14 | B17: ='Закупка'!B17 -> ARR NARCISSUS TETE-A-TETE | C17: ='Закупка'!R17 | D17: {=INDEX('Закупка'!G17:K17, $A$2)} -> 6 | E17: ='Закупка'!F17 -> 1 | F17: =IF(D17<>"",D17*E17,) -> 6 | G17: 1 | H17: 6 | K17: ='Закупка'!T17 -> 84001152 | L17: ='Закупка'!U17 -> NARCISO TETE-A-TETE - composición/14 | M17: ='Закупка'!V17
A18: ='Закупка'!A18 -> 1.15 | B18: ='Закупка'!B18 -> ARR NARCISSUS | C18: ='Закупка'!R18 | D18: {=INDEX('Закупка'!G18:K18, $A$2)} -> 4 | E18: ='Закупка'!F18 -> 1 | F18: =IF(D18<>"",D18*E18,) -> 4 | G18: 1 | H18: 4 | K18: ='Закупка'!T18 -> 84001038 | L18: ='Закупка'!U18 -> NARCIS MASCOTA - planta /17 | M18: ='Закупка'!V18
A19: ='Закупка'!A19 -> 1.16 | B19: ='Закупка'!B19 -> ARR2 PL KER BAROK DRACENA | C19: ='Закупка'!R19 | D19: {=INDEX('Закупка'!G19:K19, $A$2)} -> 4 | E19: ='Закупка'!F19 -> 1 | F19: =IF(D19<>"",D19*E19,) -> 4 | G19: 1 | H19: 4 | K19: ='Закупка'!T19 -> 84001154 | L19: ='Закупка'!U19 -> COMPOSITION DE DRECENA - planta/38 | M19: ='Закупка'!V19
A20: ='Закупка'!A20 -> 1.17 | B20: ='Закупка'!B20 -> ARR2 PL KER BAROK DRACENA | C20: ='Закупка'!R20 | D20: {=INDEX('Закупка'!G20:K20, $A$2)} | E20: ='Закупка'!F20 -> 1 | F20: =IF(D20<>"",D20*E20,) | K20: ='Закупка'!T20 -> 84001154 | L20: ='Закупка'!U20 -> COMPOSITION DE DRECENA - planta/38 | M20: ='Закупка'!V20
A21: ='Закупка'!A21 -> 1.18 | B21: ='Закупка'!B21 -> ARR2 PL GLAS CILINDER PHAL PAARS | C21: ='Закупка'!R21 | D21: {=INDEX('Закупка'!G21:K21, $A$2)} -> 2 | E21: ='Закупка'!F21 -> 1 | F21: =IF(D21<>"",D21*E21,) -> 2 | G21: 2 | H21: 2 | K21: ='Закупка'!T21 -> 84001153 | L21: ='Закупка'!U21 -> ARRANGEMENT DE PHALAENOPSIS - composición/56 | M21: ='Закупка'!V21
A22: ='Закупка'!A22 -> 1.19 | B22: ='Закупка'!B22 -> CRASSULA OVATA | C22: ='Закупка'!R22 | D22: {=INDEX('Закупка'!G22:K22, $A$2)} -> 1 | E22: ='Закупка'!F22 -> 1 | F22: =IF(D22<>"",D22*E22,) -> 1 | G22: 1 | H22: 1 | K22: ='Закупка'!T22 -> 8400365 | L22: ='Закупка'!U22 -> ARBOL DE JADE T25 -planta/120 | M22: ='Закупка'!V22 -> ARBOL DE JADE GRANDE (Crassula Ovata) T-25
A23: ='Закупка'!A23 -> 1.20 | B23: ='Закупка'!B23 -> CRASSULA OVATA | C23: ='Закупка'!R23 | D23: {=INDEX('Закупка'!G23:K23, $A$2)} | E23: ='Закупка'!F23 -> 1 | F23: =IF(D23<>"",D23*E23,) | K23: ='Закупка'!T23 -> 8400365 | L23: ='Закупка'!U23 -> ARBOL DE JADE T25 -planta/188 | M23: ='Закупка'!V23 -> ARBOL DE JADE GRANDE (Crassula Ovata) T-25
A24: ='Закупка'!A24 -> 1.21 | B24: ='Закупка'!B24 -> CODIAEUM VARI MRS ICETON | C24: ='Закупка'!R24 | D24: {=INDEX('Закупка'!G24:K24, $A$2)} -> 3 | E24: ='Закупка'!F24 -> 1 | F24: =IF(D24<>"",D24*E24,) -> 3 | G24: 3 | H24: 3 | K24: ='Закупка'!T24 -> 8400558 | L24: ='Закупка'!U24 -> CROTON 50cm - Petra - planta/36 | M24: ='Закупка'!V24 -> 81945, CROMA20
A25: ='Закупка'!A25 -> 1.22 | B25: ='Закупка'!B25 -> LAVANDULA STOE ANOUK | C25: ='Закупка'!R25 | D25: {=INDEX('Закупка'!G25:K25, $A$2)} | E25: ='Закупка'!F25 -> 1 | F25: =IF(D25<>"",D25*E25,) | K25: ='Закупка'!T25 -> 8400357 | L25: ='Закупка'!U25 -> LAVANDULA T13 - planta | M25: ='Закупка'!V25 -> LAV13 LAVANDULA T-13, 42454
A26: ='Закупка'!A26 -> 1.23 | B26: ='Закупка'!B26 -> KALANCHOE LUCKY BELLS | C26: ='Закупка'!R26 | D26: {=INDEX('Закупка'!G26:K26, $A$2)} -> 6 | E26: ='Закупка'!F26 -> 1 | F26: =IF(D26<>"",D26*E26,) -> 6 | G26: 1 | H26: 6 | K26: ='Закупка'!T26 -> 8400448 | L26: ='Закупка'!U26 -> KALANCHOE T25 - Pumila - planta/18 | M26: ='Закупка'!V26 -> KAL-P KALANCHOE PUMILA T-25 planta, KCALT
A27: ='Закупка'!A27 -> 1.24 | B27: ='Закупка'!B27 -> EUPHORBIA TRIGONA | C27: ='Закупка'!R27 | D27: {=INDEX('Закупка'!G27:K27, $A$2)} | E27: ='Закупка'!F27 -> 1 | F27: =IF(D27<>"",D27*E27,) | K27: ='Закупка'!T27 -> 8400556 | L27: ='Закупка'!U27 -> EUPHORBIA 30cm -Milii - planta/22 | M27: ='Закупка'!V27 -> 174581, EUV
A28: ='Закупка'!A28 -> 1.25 | B28: ='Закупка'!B28 -> PTPB6537 ARRANGEMENTEN PASEN | C28: ='Закупка'!R28 | D28: {=INDEX('Закупка'!G28:K28, $A$2)} -> 1 | E28: ='Закупка'!F28 -> 1 | F28: =IF(D28<>"",D28*E28,) -> 1 | G28: 1 | H28: 1 | K28: ='Закупка'!T28 -> 84001153 | L28: ='Закупка'!U28 -> ARRANGEMENT DE PHALAENOPSIS - composición/56 | M28: ='Закупка'!V28
A29: ='Закупка'!A29 -> 1.26 | B29: ='Закупка'!B29 -> PTPB6525 ARRANGEMENTEN PASEN | C29: ='Закупка'!R29 | D29: {=INDEX('Закупка'!G29:K29, $A$2)} -> 1 | E29: ='Закупка'!F29 -> 1 | F29: =IF(D29<>"",D29*E29,) -> 1 | G29: 1 | H29: 1 | K29: ='Закупка'!T29 -> 84001153 | L29: ='Закупка'!U29 -> ARRANGEMENT DE PHALAENOPSIS - composición/56 | M29: ='Закупка'!V29
A30: ='Закупка'!A30 -> 1.27 | B30: ='Закупка'!B30 -> PHALAENOPSIS OTHER YELLOW | C30: ='Закупка'!R30 | D30: {=INDEX('Закупка'!G30:K30, $A$2)} -> 6 | E30: ='Закупка'!F30 -> 1 | F30: =IF(D30<>"",D30*E30,) -> 6 | G30: 6 | H30: 6 | K30: ='Закупка'!T30 -> 8400391 | L30: ='Закупка'!U30 -> PHALAENOPSIS MIX - planta/28 | M30: ='Закупка'!V30 -> 161202, 179376, 144102, 179304, 191963, 135419, 182797, 127000, 191284
A31: ='Закупка'!A31 -> 1.28 | B31: ='Закупка'!B31 -> SUCCULENTEN OTHER | C31: ='Закупка'!R31 | D31: {=INDEX('Закупка'!G31:K31, $A$2)} | E31: ='Закупка'!F31 -> 1 | F31: =IF(D31<>"",D31*E31,) | K31: ='Закупка'!T31 -> 8400591 | L31: ='Закупка'!U31 -> SUCCULENTUS OTHER - planta/28 | M31: ='Закупка'!V31 -> CRASSCI-9, AEON.012
A32: ='Закупка'!A32 -> 1.29 | B32: ='Закупка'!B32 -> RHIPSALIS MIX | C32: ='Закупка'!R32 | D32: {=INDEX('Закупка'!G32:K32, $A$2)} -> 12 | E32: ='Закупка'!F32 -> 1 | F32: =IF(D32<>"",D32*E32,) -> 12 | G32: 1 | H32: 12 | K32: ='Закупка'!T32 -> 8400895 | L32: ='Закупка'!U32 -> RHIPSALIS MIX - T17 planta colganta | M32: ='Закупка'!V32 -> 83612
A33: ='Закупка'!A33 | B33: ='Закупка'!B33 | C33: ='Закупка'!R33 | D33: {=INDEX('Закупка'!G33:K33, $A$2)} | E33: ='Закупка'!F33 | F33: =IF(D33<>"",D33*E33,) | K33: ='Закупка'!T33 | L33: ='Закупка'!U33 | M33: ='Закупка'!V33
A34: ='Закупка'!A34 | B34: ='Закупка'!B34 | C34: ='Закупка'!R34 | D34: {=INDEX('Закупка'!G34:K34, $A$2)} | E34: ='Закупка'!F34 | F34: =IF(D34<>"",D34*E34,) | K34: ='Закупка'!T34 | L34: ='Закупка'!U34 | M34: ='Закупка'!V34
A35: ='Закупка'!A35 | B35: ='Закупка'!B35 | C35: ='Закупка'!R35 | D35: {=INDEX('Закупка'!G35:K35, $A$2)} | E35: ='Закупка'!F35 | F35: =IF(D35<>"",D35*E35,) | K35: ='Закупка'!T35 | L35: ='Закупка'!U35 | M35: ='Закупка'!V35
A36: ='Закупка'!A36 | B36: ='Закупка'!B36 | C36: ='Закупка'!R36 | D36: {=INDEX('Закупка'!G36:K36, $A$2)} | E36: ='Закупка'!F36 | F36: =IF(D36<>"",D36*E36,) | K36: ='Закупка'!T36 | L36: ='Закупка'!U36 | M36: ='Закупка'!V36
A37: ='Закупка'!A37 | B37: ='Закупка'!B37 | C37: ='Закупка'!R37 | D37: {=INDEX('Закупка'!G37:K37, $A$2)} | E37: ='Закупка'!F37 | F37: =IF(D37<>"",D37*E37,) | K37: ='Закупка'!T37 | L37: ='Закупка'!U37 | M37: ='Закупка'!V37
A38: ='Закупка'!A38 | B38: ='Закупка'!B38 | C38: ='Закупка'!R38 | D38: {=INDEX('Закупка'!G38:K38, $A$2)} | E38: ='Закупка'!F38 | F38: =IF(D38<>"",D38*E38,) | K38: ='Закупка'!T38 | L38: ='Закупка'!U38 | M38: ='Закупка'!V38
A39: ='Закупка'!A39 | B39: ='Закупка'!B39 | C39: ='Закупка'!R39 | D39: {=INDEX('Закупка'!G39:K39, $A$2)} | E39: ='Закупка'!F39 | F39: =IF(D39<>"",D39*E39,) | K39: ='Закупка'!T39 | L39: ='Закупка'!U39 | M39: ='Закупка'!V39
A40: ='Закупка'!A40 | B40: ='Закупка'!B40 | C40: ='Закупка'!R40 | D40: {=INDEX('Закупка'!G40:K40, $A$2)} | E40: ='Закупка'!F40 | F40: =IF(D40<>"",D40*E40,) | K40: ='Закупка'!T40 | L40: ='Закупка'!U40 | M40: ='Закупка'!V40
...

Sheet Blau
A1: B | B1: =VLOOKUP(A1, Lookup!B:C, 2, FALSE) -> Blau | D1: послали пачек | E1: ='Закупка'!F1 -> внтури пачки штук? | F1: послали штук товара | G1: ИМЯ флориста написать | J1: расхождение
A2: =MATCH(A1, 'Закупка'!G1:K1, 0) -> 5 | B2: ='Закупка'!B2 -> 45845 | G2: приехало пачек | H2: реально штук товара | I2: коментарий | K2: ='Закупка'!T1 -> Holded артикул | L2: ='Закупка'!U1 -> название с holded | M2: ='Закупка'!V1 -> codigo de fabricasion
A3: ='Закупка'!A3 | B3: ='Закупка'!B3 -> Фактура 1 | C3: ='Закупка'!R3 | D3: {=INDEX('Закупка'!G3:K3, $A$2)} | E3: ='Закупка'!F3 | F3: =IF(D3<>"",D3*E3,) | K3: ='Закупка'!T3 | L3: ='Закупка'!U3 | M3: ='Закупка'!V3
A4: ='Закупка'!A4 -> 1.1 | B4: ='Закупка'!B4 -> RANUNCULUS CLOONEY TUAREQ | C4: ='Закупка'!R4 | D4: {=INDEX('Закупка'!G4:K4, $A$2)} | E4: ='Закупка'!F4 -> 10 | F4: =IF(D4<>"",D4*E4,) | K4: ='Закупка'!T4 -> 8400518 | L4: ='Закупка'!U4 -> RANUNCULUS - Butterfly - flor | M4: ='Закупка'!V4 -> RANUBUBL, RANUBUSA, 174946, 147132, 126830
A5: ='Закупка'!A5 -> 1.2 | B5: ='Закупка'!B5 -> RANUNCULUS CLOONEY GRAND PASTEL | C5: ='Закупка'!R5 | D5: {=INDEX('Закупка'!G5:K5, $A$2)} -> 6 | E5: ='Закупка'!F5 -> 10 | F5: =IF(D5<>"",D5*E5,) -> 60 | G5: 6 | H5: 48 | K5: ='Закупка'!T5 -> 8400518 | L5: ='Закупка'!U5 -> RANUNCULUS - Butterfly - flor | M5: ='Закупка'!V5 -> RANUBUBL, RANUBUSA, 174946, 147132, 126830
A6: ='Закупка'!A6 -> 1.3 | B6: ='Закупка'!B6 -> ALSTROEMERIA SI SOFIENA | C6: ='Закупка'!R6 | D6: {=INDEX('Закупка'!G6:K6, $A$2)} -> 2 | E6: ='Закупка'!F6 -> 10 | F6: =IF(D6<>"",D6*E6,) -> 20 | G6: 2 | H6: 18 | K6: ='Закупка'!T6 -> 8400154 | L6: ='Закупка'!U6 -> ALSTROEMERIA - flor | M6: ='Закупка'!V6 -> 00027, 11920, 146548, 148465, ALS VA, 148462, 148466, 11920, ALS-P, 137896, 137077, 137894, 148289, 148469, ALSTROEMERIES ALSTROEMERIA, ALSP, 11920
A7: ='Закупка'!A7 -> 1.4 | B7: ='Закупка'!B7 -> ROSA LARGE BELLE ROSE | C7: ='Закупка'!R7 | D7: {=INDEX('Закупка'!G7:K7, $A$2)} -> 6 | E7: ='Закупка'!F7 -> 10 | F7: =IF(D7<>"",D7*E7,) -> 60 | G7: 6 | H7: 60 | K7: ='Закупка'!T7 -> 8400731 | L7: ='Закупка'!U7 -> RS ROSA LA BELLE LOLOMARIK - flor | M7: ='Закупка'!V7 -> 181496
A8: ='Закупка'!A8 -> 1.5 | B8: ='Закупка'!B8 -> ROSA GARDEN PRISCILLA! | C8: ='Закупка'!R8 | D8: {=INDEX('Закупка'!G8:K8, $A$2)} -> 4 | E8: ='Закупка'!F8 -> 5 | F8: =IF(D8<>"",D8*E8,) -> 20 | G8: 4 | H8: 20 | K8: ='Закупка'!T8 -> 84001081 | L8: ='Закупка'!U8 -> ROSA PRISCILLA - flor | M8: ='Закупка'!V8
A9: ='Закупка'!A9 -> 1.6 | B9: ='Закупка'!B9 -> ROSA GARDEN MIX UHURU | C9: ='Закупка'!R9 | D9: {=INDEX('Закупка'!G9:K9, $A$2)} -> 8 | E9: ='Закупка'!F9 -> 6 | F9: =IF(D9<>"",D9*E9,) -> 48 | G9: 8 | H9: 46 | K9: ='Закупка'!T9 -> 84001157 | L9: ='Закупка'!U9 -> RISA GARDAN MIX - flor/3 | M9: ='Закупка'!V9
A10: ='Закупка'!A10 -> 1.7 | B10: ='Закупка'!B10 -> ROSA SPRAY CHIMO | C10: ='Закупка'!R10 | D10: {=INDEX('Закупка'!G10:K10, $A$2)} -> 3 | E10: ='Закупка'!F10 -> 10 | F10: =IF(D10<>"",D10*E10,) -> 30 | G10: 3 | H10: 30 | K10: ='Закупка'!T10 -> 8400828 | L10: ='Закупка'!U10 -> ROSA CHIMO - flor | M10: ='Закупка'!V10 -> 135409
A11: ='Закупка'!A11 -> 1.8 | B11: ='Закупка'!B11 -> ROSA SPRAY BIRDS NEST+ | C11: ='Закупка'!R11 | D11: {=INDEX('Закупка'!G11:K11, $A$2)} -> 3 | E11: ='Закупка'!F11 -> 10 | F11: =IF(D11<>"",D11*E11,) -> 30 | G11: 3 | H11: 30 | K11: ='Закупка'!T11 -> 84001078 | L11: ='Закупка'!U11 -> ROSA BIRDS NEST - flor | M11: ='Закупка'!V11
A12: ='Закупка'!A12 -> 1.9 | B12: ='Закупка'!B12 -> ROSA LARGE CELEB | C12: ='Закупка'!R12 | D12: {=INDEX('Закупка'!G12:K12, $A$2)} | E12: ='Закупка'!F12 -> 10 | F12: =IF(D12<>"",D12*E12,) | K12: ='Закупка'!T12 -> 84001044 | L12: ='Закупка'!U12 -> ROSA CELEBRATING HEATHER - flor | M12: ='Закупка'!V12
A13: ='Закупка'!A13 -> 1.10 | B13: ='Закупка'!B13 -> ARR CACTUS | C13: ='Закупка'!R13 | D13: {=INDEX('Закупка'!G13:K13, $A$2)} -> 9 | E13: ='Закупка'!F13 -> 1 | F13: =IF(D13<>"",D13*E13,) -> 9 | G13: 9 | H13: 9 | K13: ='Закупка'!T13 -> 8400594 | L13: ='Закупка'!U13 -> CACTUS - planta/22 | M13: ='Закупка'!V13 -> TEST 13 cactus
A14: ='Закупка'!A14 -> 1.11 | B14: ='Закупка'!B14 -> ALOE ARBO | C14: ='Закупка'!R14 | D14: {=INDEX('Закупка'!G14:K14, $A$2)} | E14: ='Закупка'!F14 -> 1 | F14: =IF(D14<>"",D14*E14,) | K14: ='Закупка'!T14 -> 84001156 | L14: ='Закупка'!U14 -> ALOE ARBO - planta/67 | M14: ='Закупка'!V14
A15: ='Закупка'!A15 -> 1.12 | B15: ='Закупка'!B15 -> ALOE ARBO | C15: ='Закупка'!R15 | D15: {=INDEX('Закупка'!G15:K15, $A$2)} -> 4 | E15: ='Закупка'!F15 -> 1 | F15: =IF(D15<>"",D15*E15,) -> 4 | G15: 4 | H15: 4 | K15: ='Закупка'!T15 -> 84001155 | L15: ='Закупка'!U15 -> ALOE ARBO - planta/47 | M15: ='Закупка'!V15
A16: ='Закупка'!A16 -> 1.13 | B16: ='Закупка'!B16 -> ARR2 MB GROEN IJZER REK 1 BOL | C16: ='Закупка'!R16 | D16: {=INDEX('Закупка'!G16:K16, $A$2)} -> 4 | E16: ='Закупка'!F16 -> 1 | F16: =IF(D16<>"",D16*E16,) -> 4 | G16: 4 | H16: 4 | K16: ='Закупка'!T16 -> 8400410 | L16: ='Закупка'!U16 -> SUCCULENTUS T16, T22 - MIX - planta/22 | M16: ='Закупка'!V16 -> 6CRASA22, 54, CRASS16
A17: ='Закупка'!A17 -> 1.14 | B17: ='Закупка'!B17 -> ARR NARCISSUS TETE-A-TETE | C17: ='Закупка'!R17 | D17: {=INDEX('Закупка'!G17:K17, $A$2)} -> 6 | E17: ='Закупка'!F17 -> 1 | F17: =IF(D17<>"",D17*E17,) -> 6 | G17: 6 | H17: 6 | K17: ='Закупка'!T17 -> 84001152 | L17: ='Закупка'!U17 -> NARCISO TETE-A-TETE - composición/14 | M17: ='Закупка'!V17
A18: ='Закупка'!A18 -> 1.15 | B18: ='Закупка'!B18 -> ARR NARCISSUS | C18: ='Закупка'!R18 | D18: {=INDEX('Закупка'!G18:K18, $A$2)} -> 4 | E18: ='Закупка'!F18 -> 1 | F18: =IF(D18<>"",D18*E18,) -> 4 | G18: 4 | H18: 4 | K18: ='Закупка'!T18 -> 84001038 | L18: ='Закупка'!U18 -> NARCIS MASCOTA - planta /17 | M18: ='Закупка'!V18
